Workbook
Name ColTypes: الإعدادات!$D$2:$D$6
Name DistTypes: الإعدادات!$B$2:$B$8
Name ExpTypes: الإعدادات!$C$2:$C$11
Name InvList: Tbl_Investors[اسم المساهم]
Name ProjList: Tbl_Projects[اسم المشروع]
Name ProjStatus: الإعدادات!$A$2:$A$5

Sheet الإعدادات
A1: ProjStatus | B1: DistTypes | C1: ExpTypes | D1: ColTypes
A2: تحت الدراسة | B2: توزيع أرباح | C2: إدارة | D2: دفعة أولى
A3: قيد التنفيذ | B3: رد رأس مال | C3: عمولة | D3: دفعة ثانية
A4: مكتمل | B4: مسحوب للمساهم | C4: ضرائب | D4: دفعة إضافية
A5: متوقف | B5: مسحوب للإدارة | C5: مقاولات | D5: تحصيل نهائي
B6: تسوية | C6: تشطيب | D6: تحويل وارد
B7: تحويل بين المشاريع | C7: شراء
B8: أخرى | C8: تسويق
C9: قانوني
C10: مصاريف تشغيل
C11: أخرى

Sheet المساهمون
A2: كود المساهم | B2: اسم المساهم | C2: رقم الهاتف | D2: ملاحظات
A3: INV-001 | B3: ابو سامح
A4: INV-002 | B4: وليد مصطفى
A5: INV-003 | B5: مايز محمد
A6: INV-004 | B6: زكريا على
A7: INV-005 | B7: رمضان رجب
A8: INV-006 | B8: اشرف ابراهيم
A9: INV-007 | B9: على ممدوح
A10: INV-008 | B10: عمر صلاح
A11: INV-009 | B11: جمعه خلف
A12: INV-010 | B12: محمد ناجى
A13: INV-011 | B13: عماد تقى نقى
A14: INV-012 | B14: امدحت
... A30: INV-034 | B30: م ماجد تكييف
A31: INV-035
A32: INV-036
A33: INV-037
A34: INV-038
A35: INV-039
A36: INV-040
A37: INV-041
A38: INV-042
A39: INV-043
A40: INV-044
A41: INV-045
A42: INV-046
... A46: INV-050

Sheet المشاريع
A2: كود المشروع | B2: اسم المشروع | C2: نوع المشروع | D2: تاريخ البداية | E2: تاريخ النهاية | F2: حالة المشروع | G2: إجمالي رأس المال | H2: إجمالي التحصيل المتوقع | I2: إجمالي التحصيل الفعلي | J2: التحويلات الواردة | K2: التحويلات الصادرة | L2: إجمالي المصروفات | M2: صافي الربح | N2: السيولة المتبقية بالمشروع | O2: ملاحظات | P2: إجمالي قيمة المبيعات | Q2: المبيعات الكاش | R2: المبيعات بالتقسيط | S2: إجمالي التحصيلات (مبيعات) | T2: المتبقي من المبيعات
A3: PRJ-001 | B3: 8842 | C3: عقاري | D3: 45901 | E3: 46446 | F3: قيد التنفيذ | G3: =SUMIFS(Tbl_Contributions[رأس مال المساهم], Tbl_Contributions[اسم المشروع], Tbl_Projects[[#This Row],[اسم المشروع]]) -> 15000000 | H3: 0 | I3: =SUMIFS(Tbl_Collections[المبلغ], Tbl_Collections[المشروع], Tbl_Projects[[#This Row],[اسم المشروع]], Tbl_Collections[نوع التحصيل], "<>تحويل وارد") -> 8569000 | J3: =SUMIFS(Tbl_Distributions[المبلغ],#REF!, Tbl_Projects[[#This Row],[اسم المشروع]], Tbl_Distributions[نوع العملية], "تحويل بين المشاريع") -> #REF! | K3: =SUMIFS(Tbl_Distributions[المبلغ], Tbl_Distributions[المشروع المصدر], Tbl_Projects[[#This Row],[اسم المشروع]], Tbl_Distributions[نوع العملية], "تحويل بين المشاريع") -> 0 | L3: =SUMIFS(Tbl_Expenses[المبلغ], Tbl_Expenses[المشروع], Tbl_Projects[[#This Row],[اسم المشروع]]) -> 0 | M3: =Tbl_Projects[[#This Row],[إجمالي التحصيل الفعلي]] - Tbl_Projects[[#This Row],[إجمالي رأس المال]] - Tbl_Projects[[#This Row],[إجمالي المصروفات]] -> -6431000 | N3: =Tbl_Projects[[#This Row],[إجمالي التحصيل الفعلي]] + Tbl_Projects[[#This Row],[التحويلات الواردة]] - Tbl_Projects[[#This Row],[إجمالي المصروفات]] - Tbl_Projects[[#This Row],[التحويلات الصادرة]] - SUMIFS(Tbl_Distributions[المبلغ], Tbl_Distributions[المشروع المصدر], Tbl_Projects[[#This Row],[اسم المشروع]], Tbl_Distributions[نوع العملية], "<>تحويل بين المشاريع") -> #REF! | P3: =IF(A3="","", SUMIFS(المبيعات!$G:$G, المبيعات!$B:$B, A3)) -> 0 | Q3: =IF(A3="","", SUMIFS(المبيعات!$G:$G, المبيعات!$B:$B, A3, المبيعات!$H:$H, "كاش")) -> 0 | R3: =IF(A3="","", SUMIFS(المبيعات!$G:$G, المبيعات!$B:$B, A3, المبيعات!$H:$H, "تقسيط")) -> 0 | S3: =IF(A3="","", SUMIFS(المبيعات!$O:$O, المبيعات!$B:$B, A3)) -> 0 | T3: =IF(A3="","", P3 - S3) -> 0
A4: PRJ-002 | B4: مصر للتامين | C4: عقارى | D4: 45658 | E4: 46752 | F4: متوقف | G4: =SUMIFS(Tbl_Contributions[رأس مال المساهم], Tbl_Contributions[اسم المشروع], Tbl_Projects[[#This Row],[اسم المشروع]]) -> 13000000 | I4: =SUMIFS(Tbl_Collections[المبلغ], Tbl_Collections[المشروع], Tbl_Projects[[#This Row],[اسم المشروع]], Tbl_Collections[نوع التحصيل], "<>تحويل وارد") -> 0 | K4: =SUMIFS(Tbl_Distributions[المبلغ], Tbl_Distributions[المشروع المصدر], Tbl_Projects[[#This Row],[اسم المشروع]], Tbl_Distributions[نوع العملية], "تحويل بين المشاريع") -> 0 | L4: =SUMIFS(Tbl_Expenses[المبلغ], Tbl_Expenses[المشروع], Tbl_Projects[[#This Row],[اسم المشروع]]) -> 0 | M4: =Tbl_Projects[[#This Row],[إجمالي التحصيل الفعلي]] - Tbl_Projects[[#This Row],[إجمالي رأس المال]] - Tbl_Projects[[#This Row],[إجمالي المصروفات]] -> -13000000 | N4: =Tbl_Projects[[#This Row],[إجمالي التحصيل الفعلي]] + Tbl_Projects[[#This Row],[التحويلات الواردة]] - Tbl_Projects[[#This Row],[إجمالي المصروفات]] - Tbl_Projects[[#This Row],[التحويلات الصادرة]] - SUMIFS(Tbl_Distributions[المبلغ], Tbl_Distributions[المشروع المصدر], Tbl_Projects[[#This Row],[اسم المشروع]], Tbl_Distributions[نوع العملية], "<>تحويل بين المشاريع") -> 0 | P4: =IF(A4="","", SUMIFS(المبيعات!$G:$G, المبيعات!$B:$B, A4)) -> 0 | Q4: =IF(A4="","", SUMIFS(المبيعات!$G:$G, المبيعات!$B:$B, A4, المبيعات!$H:$H, "كاش")) -> 0 | R4: =IF(A4="","", SUMIFS(المبيعات!$G:$G, المبيعات!$B:$B, A4, المبيعات!$H:$H, "تقسيط")) -> 0 | S4: =IF(A4="","", SUMIFS(المبيعات!$O:$O, المبيعات!$B:$B, A4)) -> 0 | T4: =IF(A4="","", P4 - S4) -> 0
A5: PRJ-003 | B5: خلف قطعة بلال قطعه 12 | C5: عقارى | D5: 46023 | E5: 46568 | F5: قيد التنفيذ | G5: =SUMIFS(Tbl_Contributions[رأس مال المساهم], Tbl_Contributions[اسم المشروع], Tbl_Projects[[#This Row],[اسم المشروع]]) -> 5000000 | I5: =SUMIFS(Tbl_Collections[المبلغ], Tbl_Collections[المشروع], Tbl_Projects[[#This Row],[اسم المشروع]], Tbl_Collections[نوع التحصيل], "<>تحويل وارد") -> 0 | K5: =SUMIFS(Tbl_Distributions[المبلغ], Tbl_Distributions[المشروع المصدر], Tbl_Projects[[#This Row],[اسم المشروع]], Tbl_Distributions[نوع العملية], "تحويل بين المشاريع") -> 0 | L5: =SUMIFS(Tbl_Expenses[المبلغ], Tbl_Expenses[المشروع], Tbl_Projects[[#This Row],[اسم المشروع]]) -> 0 | M5: =Tbl_Projects[[#This Row],[إجمالي التحصيل الفعلي]] - Tbl_Projects[[#This Row],[إجمالي رأس المال]] - Tbl_Projects[[#This Row],[إجمالي المصروفات]] -> -5000000 | N5: =Tbl_Projects[[#This Row],[إجمالي التحصيل الفعلي]] + Tbl_Projects[[#This Row],[التحويلات الواردة]] - Tbl_Projects[[#This Row],[إجمالي المصروفات]] - Tbl_Projects[[#This Row],[التحويلات الصادرة]] - SUMIFS(Tbl_Distributions[المبلغ], Tbl_Distributions[المشروع المصدر], Tbl_Projects[[#This Row],[اسم المشروع]], Tbl_Distributions[نوع العملية], "<>تحويل بين المشاريع") -> 0 | P5: =IF(A5="","", SUMIFS(المبيعات!$G:$G, المبيعات!$B:$B, A5)) -> 0 | Q5: =IF(A5="","", SUMIFS(المبيعات!$G:$G, المبيعات!$B:$B, A5, المبيعات!$H:$H, "كاش")) -> 0 | R5: =IF(A5="","", SUMIFS(المبيعات!$G:$G, المبيعات!$B:$B, A5, المبيعات!$H:$H, "تقسيط")) -> 0 | S5: =IF(A5="","", SUMIFS(المبيعات!$O:$O, المبيعات!$B:$B, A5)) -> 0 | T5: =IF(A5="","", P5 - S5) -> 0
A6: PRJ-004 | B6: شقة الاكاديمية | C6: عقارى | D6: 46054 | E6: 46259 | F6: مكتمل | G6: =SUMIFS(Tbl_Contributions[رأس مال المساهم], Tbl_Contributions[اسم المشروع], Tbl_Projects[[#This Row],[اسم المشروع]]) -> 3100000 | I6: =SUMIFS(Tbl_Collections[المبلغ], Tbl_Collections[المشروع], Tbl_Projects[[#This Row],[اسم المشروع]], Tbl_Collections[نوع التحصيل], "<>تحويل وارد") -> 4000000 | K6: =SUMIFS(Tbl_Distributions[المبلغ], Tbl_Distributions[المشروع المصدر], Tbl_Projects[[#This Row],[اسم المشروع]], Tbl_Distributions[نوع العملية], "تحويل بين المشاريع") -> 0 | L6: =SUMIFS(Tbl_Expenses[المبلغ], Tbl_Expenses[المشروع], Tbl_Projects[[#This Row],[اسم المشروع]]) -> 180000 | M6: =Tbl_Projects[[#This Row],[إجمالي التحصيل الفعلي]] - Tbl_Projects[[#This Row],[إجمالي رأس المال]] - Tbl_Projects[[#This Row],[إجمالي المصروفات]] -> 720000 | N6: =Tbl_Projects[[#This Row],[إجمالي التحصيل الفعلي]] + Tbl_Projects[[#This Row],[التحويلات الواردة]] - Tbl_Projects[[#This Row],[إجمالي المصروفات]] - Tbl_Projects[[#This Row],[التحويلات الصادرة]] - SUMIFS(Tbl_Distributions[المبلغ], Tbl_Distributions[المشروع المصدر], Tbl_Projects[[#This Row],[اسم المشروع]], Tbl_Distributions[نوع العملية], "<>تحويل بين المشاريع") -> 3820000 | P6: =IF(A9="","", SUMIFS(المبيعات!$G:$G, المبيعات!$B:$B, A9)) | Q6: =IF(A9="","", SUMIFS(المبيعات!$G:$G, المبيعات!$B:$B, A9, المبيعات!$H:$H, "كاش")) | R6: =IF(A9="","", SUMIFS(المبيعات!$G:$G, المبيعات!$B:$B, A9, المبيعات!$H:$H, "تقسيط")) | S6: =IF(A9="","", SUMIFS(المبيعات!$O:$O, المبيعات!$B:$B, A9)) | T6: =IF(A9="","", P6 - S6)
A7: PRJ-005 | B7: شارع ابو شقره | C7: عقارى | D7: 46188 | E7: 46752 | F7: قيد التنفيذ | G7: =SUMIFS(Tbl_Contributions[رأس مال المساهم], Tbl_Contributions[اسم المشروع], Tbl_Projects[[#This Row],[اسم المشروع]]) -> 5500000 | I7: =SUMIFS(Tbl_Collections[المبلغ], Tbl_Collections[المشروع], Tbl_Projects[[#This Row],[اسم المشروع]], Tbl_Collections[نوع التحصيل], "<>تحويل وارد") -> 0 | K7: =SUMIFS(Tbl_Distributions[المبلغ], Tbl_Distributions[المشروع المصدر], Tbl_Projects[[#This Row],[اسم المشروع]], Tbl_Distributions[نوع العملية], "تحويل بين المشاريع") -> 0 | L7: =SUMIFS(Tbl_Expenses[المبلغ], Tbl_Expenses[المشروع], Tbl_Projects[[#This Row],[اسم المشروع]]) -> 0 | M7: =Tbl_Projects[[#This Row],[إجمالي التحصيل الفعلي]] - Tbl_Projects[[#This Row],[إجمالي رأس المال]] - Tbl_Projects[[#This Row],[إجمالي المصروفات]] -> -5500000 | N7: =Tbl_Projects[[#This Row],[إجمالي التحصيل الفعلي]] + Tbl_Projects[[#This Row],[التحويلات الواردة]] - Tbl_Projects[[#This Row],[إجمالي المصروفات]] - Tbl_Projects[[#This Row],[التحويلات الصادرة]] - SUMIFS(Tbl_Distributions[المبلغ], Tbl_Distributions[المشروع المصدر], Tbl_Projects[[#This Row],[اسم المشروع]], Tbl_Distributions[نوع العملية], "<>تحويل بين المشاريع") -> 0 | P7: =IF(A10="","", SUMIFS(المبيعات!$G:$G, المبيعات!$B:$B, A10)) | Q7: =IF(A10="","", SUMIFS(المبيعات!$G:$G, المبيعات!$B:$B, A10, المبيعات!$H:$H, "كاش")) | R7: =IF(A10="","", SUMIFS(المبيعات!$G:$G, المبيعات!$B:$B, A10, المبيعات!$H:$H, "تقسيط")) | S7: =IF(A10="","", SUMIFS(المبيعات!$O:$O, المبيعات!$B:$B, A10)) | T7: =IF(A10="","", P7 - S7)
G8: =SUMIFS(Tbl_Contributions[رأس مال المساهم], Tbl_Contributions[اسم المشروع], Tbl_Projects[[#This Row],[اسم المشروع]]) -> 0 | I8: =SUMIFS(Tbl_Collections[المبلغ], Tbl_Collections[المشروع], Tbl_Projects[[#This Row],[اسم المشروع]], Tbl_Collections[نوع التحصيل], "<>تحويل وارد") -> 0 | K8: =SUMIFS(Tbl_Distributions[المبلغ], Tbl_Distributions[المشروع المصدر], Tbl_Projects[[#This Row],[اسم المشروع]], Tbl_Distributions[نوع العملية], "تحويل بين المشاريع") -> 0 | L8: =SUMIFS(Tbl_Expenses[المبلغ], Tbl_Expenses[المشروع], Tbl_Projects[[#This Row],[اسم المشروع]]) -> 0 | M8: =Tbl_Projects[[#This Row],[إجمالي التحصيل الفعلي]] - Tbl_Projects[[#This Row],[إجمالي رأس المال]] - Tbl_Projects[[#This Row],[إجمالي المصروفات]] -> 0 | N8: =Tbl_Projects[[#This Row],[إجمالي التحصيل الفعلي]] + Tbl_Projects[[#This Row],[التحويلات الواردة]] - Tbl_Projects[[#This Row],[إجمالي المصروفات]] - Tbl_Projects[[#This Row],[التحويلات الصادرة]] - SUMIFS(Tbl_Distributions[المبلغ], Tbl_Distributions[المشروع المصدر], Tbl_Projects[[#This Row],[اسم المشروع]], Tbl_Distributions[نوع العملية], "<>تحويل بين المشاريع") -> 0 | P8: =IF(A11="","", SUMIFS(المبيعات!$G:$G, المبيعات!$B:$B, A11)) | Q8: =IF(A11="","", SUMIFS(المبيعات!$G:$G, المبيعات!$B:$B, A11, المبيعات!$H:$H, "كاش")) | R8: =IF(A11="","", SUMIFS(المبيعات!$G:$G, المبيعات!$B:$B, A11, المبيعات!$H:$H, "تقسيط")) | S8: =IF(A11="","", SUMIFS(المبيعات!$O:$O, المبيعات!$B:$B, A11)) | T8: =IF(A11="","", P8 - S8)
F9: قيد التنفيذ | J9: 0 | K9: 0 | L9: 0 | P9: =IF(A12="","", SUMIFS(المبيعات!$G:$G, المبيعات!$B:$B, A12)) | Q9: =IF(A12="","", SUMIFS(المبيعات!$G:$G, المبيعات!$B:$B, A12, المبيعات!$H:$H, "كاش")) | R9: =IF(A12="","", SUMIFS(المبيعات!$G:$G, المبيعات!$B:$B, A12, المبيعات!$H:$H, "تقسيط")) | S9: =IF(A12="","", SUMIFS(المبيعات!$O:$O, المبيعات!$B:$B, A12)) | T9: =IF(A12="","", P9 - S9)
P10: =IF(A13="","", SUMIFS(المبيعات!$G:$G, المبيعات!$B:$B, A13)) | Q10: =IF(A13="","", SUMIFS(المبيعات!$G:$G, المبيعات!$B:$B, A13, المبيعات!$H:$H, "كاش")) | R10: =IF(A13="","", SUMIFS(المبيعات!$G:$G, المبيعات!$B:$B, A13, المبيعات!$H:$H, "تقسيط")) | S10: =IF(A13="","", SUMIFS(المبيعات!$O:$O, المبيعات!$B:$B, A13)) | T10: =IF(A13="","", P10 - S10)
P11: =IF(A14="","", SUMIFS(المبيعات!$G:$G, المبيعات!$B:$B, A14)) | Q11: =IF(A14="","", SUMIFS(المبيعات!$G:$G, المبيعات!$B:$B, A14, المبيعات!$H:$H, "كاش")) | R11: =IF(A14="","", SUMIFS(المبيعات!$G:$G, المبيعات!$B:$B, A14, المبيعات!$H:$H, "تقسيط")) | S11: =IF(A14="","", SUMIFS(المبيعات!$O:$O, المبيعات!$B:$B, A14)) | T11: =IF(A14="","", P11 - S11)
P12: =IF(A15="","", SUMIFS(المبيعات!$G:$G, المبيعات!$B:$B, A15)) | Q12: =IF(A15="","", SUMIFS(المبيعات!$G:$G, المبيعات!$B:$B, A15, المبيعات!$H:$H, "كاش")) | R12: =IF(A15="","", SUMIFS(المبيعات!$G:$G, المبيعات!$B:$B, A15, المبيعات!$H:$H, "تقسيط")) | S12: =IF(A15="","", SUMIFS(المبيعات!$O:$O, المبيعات!$B:$B, A15)) | T12: =IF(A15="","", P12 - S12)
P13: =IF(A16="","", SUMIFS(المبيعات!$G:$G, المبيعات!$B:$B, A16)) | Q13: =IF(A16="","", SUMIFS(المبيعات!$G:$G, المبيعات!$B:$B, A16, المبيعات!$H:$H, "كاش")) | R13: =IF(A16="","", SUMIFS(المبيعات!$G:$G, المبيعات!$B:$B, A16, المبيعات!$H:$H, "تقسيط")) | S13: =IF(A16="","", SUMIFS(المبيعات!$O:$O, المبيعات!$B:$B, A16)) | T13: =IF(A16="","", P13 - S13)
P14: =IF(A17="","", SUMIFS(المبيعات!$G:$G, المبيعات!$B:$B, A17)) | Q14: =IF(A17="","", SUMIFS(المبيعات!$G:$G, المبيعات!$B:$B, A17, المبيعات!$H:$H, "كاش")) | R14: =IF(A17="","", SUMIFS(المبيعات!$G:$G, المبيعات!$B:$B, A17, المبيعات!$H:$H, "تقسيط")) | S14: =IF(A17="","", SUMIFS(المبيعات!$O:$O, المبيعات!$B:$B, A17)) | T14: =IF(A17="","", P14 - S14)
P15: =IF(A18="","", SUMIFS(المبيعات!$G:$G, المبيعات!$B:$B, A18)) | Q15: =IF(A18="","", SUMIFS(المبيعات!$G:$G, المبيعات!$B:$B, A18, المبيعات!$H:$H, "كاش")) | R15: =IF(A18="","", SUMIFS(المبيعات!$G:$G, المبيعات!$B:$B, A18, المبيعات!$H:$H, "تقسيط")) | S15: =IF(A18="","", SUMIFS(المبيعات!$O:$O, المبيعات!$B:$B, A18)) | T15: =IF(A18="","", P15 - S15)
P16: =IF(A19="","", SUMIFS(المبيعات!$G:$G, المبيعات!$B:$B, A19)) | Q16: =IF(A19="","", SUMIFS(المبيعات!$G:$G, المبيعات!$B:$B, A19, المبيعات!$H:$H, "كاش")) | R16: =IF(A19="","", SUMIFS(المبيعات!$G:$G, المبيعات!$B:$B, A19, المبيعات!$H:$H, "تقسيط")) | S16: =IF(A19="","", SUMIFS(المبيعات!$O:$O, المبيعات!$B:$B, A19)) | T16: =IF(A19="","", P16 - S16)
P17: =IF(A20="","", SUMIFS(المبيعات!$G:$G, المبيعات!$B:$B, A20)) | Q17: =IF(A20="","", SUMIFS(المبيعات!$G:$G, المبيعات!$B:$B, A20, المبيعات!$H:$H, "كاش")) | R17: =IF(A20="","", SUMIFS(المبيعات!$G:$G, المبيعات!$B:$B, A20, المبيعات!$H:$H, "تقسيط")) | S17: =IF(A20="","", SUMIFS(المبيعات!$O:$O, المبيعات!$B:$B, A20)) | T17: =IF(A20="","", P17 - S17)
P18: =IF(A21="","", SUMIFS(المبيعات!$G:$G, المبيعات!$B:$B, A21)) | Q18: =IF(A21="","", SUMIFS(المبيعات!$G:$G, المبيعات!$B:$B, A21, المبيعات!$H:$H, "كاش")) | R18: =IF(A21="","", SUMIFS(المبيعات!$G:$G, المبيعات!$B:$B, A21, المبيعات!$H:$H, "تقسيط")) | S18: =IF(A21="","", SUMIFS(المبيعات!$O:$O, المبيعات!$B:$B, A21)) | T18: =IF(A21="","", P18 - S18)
P19: =IF(A22="","", SUMIFS(المبيعات!$G:$G, المبيعات!$B:$B, A22)) | Q19: =IF(A22="","", SUMIFS(المبيعات!$G:$G, المبيعات!$B:$B, A22, المبيعات!$H:$H, "كاش")) | R19: =IF(A22="","", SUMIFS(المبيعات!$G:$G, المبيعات!$B:$B, A22, المبيعات!$H:$H, "تقسيط")) | S19: =IF(A22="","", SUMIFS(المبيعات!$O:$O, المبيعات!$B:$B, A22)) | T19: =IF(A22="","", P19 - S19)
P20: =IF(A23="","", SUMIFS(المبيعات!$G:$G, المبيعات!$B:$B, A23)) | Q20: =IF(A23="","", SUMIFS(المبيعات!$G:$G, المبيعات!$B:$B, A23, المبيعات!$H:$H, "كاش")) | R20: =IF(A23="","", SUMIFS(المبيعات!$G:$G, المبيعات!$B:$B, A23, المبيعات!$H:$H, "تقسيط")) | S20: =IF(A23="","", SUMIFS(المبيعات!$O:$O, المبيعات!$B:$B, A23)) | T20: =IF(A23="","", P20 - S20)
P21: =IF(A24="","", SUMIFS(المبيعات!$G:$G, المبيعات!$B:$B, A24)) | Q21: =IF(A24="","", SUMIFS(المبيعات!$G:$G, المبيعات!$B:$B, A24, المبيعات!$H:$H, "كاش")) | R21: =IF(A24="","", SUMIFS(المبيعات!$G:$G, المبيعات!$B:$B, A24, المبيعات!$H:$H, "تقسيط")) | S21: =IF(A24="","", SUMIFS(المبيعات!$O:$O, المبيعات!$B:$B, A24)) | T21: =IF(A24="","", P21 - S21)
... P99: =IF(A102="","", SUMIFS(المبيعات!$G:$G, المبيعات!$B:$B, A102)) | Q99: =IF(A102="","", SUMIFS(المبيعات!$G:$G, المبيعات!$B:$B, A102, المبيعات!$H:$H, "كاش")) | R99: =IF(A102="","", SUMIFS(المبيعات!$G:$G, المبيعات!$B:$B, A102, المبيعات!$H:$H, "تقسيط")) | S99: =IF(A102="","", SUMIFS(المبيعات!$O:$O, المبيعات!$B:$B, A102)) | T99: =IF(A102="","", P99 - S99)

Sheet مساهمات المشاريع
A2: كود المشروع | B2: اسم المشروع | C2: كود المساهم | D2: اسم المساهم | E2: رأس مال المساهم | F2: نسبة مساهمته | G2: نسبة الإدارة الخاصة به | H2: حصة الربح قبل الإدارة | I2: نصيب الإدارة | J2: صافي ربح المساهم | K2: إجمالي المستحق للمساهم | L2: المسحوبات (تتضمن رد رأس المال والأرباح) | M2: مسحوبات الإدارة (إن وجدت) | N2: المتبقي للمساهم | O2: ملاحظات (تنبيه نسبة الإدارة)
A3: =IFERROR(INDEX([1]!Tbl_Projects[كود المشروع], MATCH([1]!Tbl_Contributions[[#This Row],[اسم المشروع]], [1]!Tbl_Projects[اسم المشروع], 0)), "") | B3: 8842 | C3: =IFERROR(INDEX([1]!Tbl_Investors[كود المساهم], MATCH([1]!Tbl_Contributions[[#This Row],[اسم المساهم]], [1]!Tbl_Investors[اسم المساهم], 0)), "") | D3: ابو سامح | E3: 2600000 | F3: =IF(SUMIFS(Tbl_Contributions[رأس مال المساهم], Tbl_Contributions[اسم المشروع], Tbl_Contributions[[#This Row],[اسم المشروع]])=0, 0, Tbl_Contributions[[#This Row],[رأس مال المساهم]]/SUMIFS(Tbl_Contributions[رأس مال المساهم], Tbl_Contributions[اسم المشروع], Tbl_Contributions[[#This Row],[اسم المشروع]])) -> 0.17333333 | G3: 0.2 | H3: =IFERROR(INDEX(Tbl_Projects[صافي الربح], MATCH(Tbl_Contributions[[#This Row],[اسم المشروع]], Tbl_Projects[اسم المشروع], 0)) * Tbl_Contributions[[#This Row],[نسبة مساهمته]], 0) -> -1114706.7 | I3: =IF(AND(ISNUMBER(Tbl_Contributions[[#This Row],[نسبة الإدارة الخاصة به]]), Tbl_Contributions[[#This Row],[حصة الربح قبل الإدارة]]>0), Tbl_Contributions[[#This Row],[حصة الربح قبل الإدارة]] * Tbl_Contributions[[#This Row],[نسبة الإدارة الخاصة به]], 0) -> 0 | J3: =Tbl_Contributions[[#This Row],[حصة الربح قبل الإدارة]] - Tbl_Contributions[[#This Row],[نصيب الإدارة]] -> -1114706.7 | K3: =Tbl_Contributions[[#This Row],[رأس مال المساهم]] + Tbl_Contributions[[#This Row],[صافي ربح المساهم]] -> 1485293.3 | L3: =SUMIFS(Tbl_Distributions[المبلغ], Tbl_Distributions[المشروع المصدر], Tbl_Contributions[[#This Row],[اسم المشروع]], Tbl_Distributions[المساهم], Tbl_Contributions[[#This Row],[اسم المساهم]], Tbl_Distributions[نوع العملية], "<>تحويل بين المشاريع", Tbl_Distributions[نوع العملية], "<>مسحوب للإدارة") -> 1485000 | M3: =SUMIFS(Tbl_Distributions[المبلغ], Tbl_Distributions[المشروع المصدر], Tbl_Contributions[[#This Row],[اسم المشروع]], Tbl_Distributions[المساهم], Tbl_Contributions[[#This Row],[اسم المساهم]], Tbl_Distributions[نوع العملية], "مسحوب للإدارة") -> 0 | N3: =Tbl_Contributions[[#This Row],[إجمالي المستحق للمساهم]] - Tbl_Contributions[[#This Row],[المسحوبات (تتضمن رد رأس المال والأرباح)]] -> 293.33333 | O3: =IF(ISBLANK(Tbl_Contributions[[#This Row],[نسبة الإدارة الخاصة به]]), "تنبيه: نسبة الإدارة غير مسجلة", "مكتمل") -> مكتمل
A4: =IFERROR(INDEX([1]!Tbl_Projects[كود المشروع], MATCH([1]!Tbl_Contributions[[#This Row],[اسم المشروع]], [1]!Tbl_Projects[اسم المشروع], 0)), "") | B4: 8842 | C4: =IFERROR(INDEX([1]!Tbl_Investors[كود المساهم], MATCH([1]!Tbl_Contributions[[#This Row],[اسم المساهم]], [1]!Tbl_Investors[اسم المساهم], 0)), "") | D4: وليد مصطفى | E4: 1000000 | F4: =IF(SUMIFS(Tbl_Contributions[رأس مال المساهم], Tbl_Contributions[اسم المشروع], Tbl_Contributions[[#This Row],[اسم المشروع]])=0, 0, Tbl_Contributions[[#This Row],[رأس مال المساهم]]/SUMIFS(Tbl_Contributions[رأس مال المساهم], Tbl_Contributions[اسم المشروع], Tbl_Contributions[[#This Row],[اسم المشروع]])) -> 0.066666667 | G4: 0.2 | H4: =IFERROR(INDEX(Tbl_Projects[صافي الربح], MATCH(Tbl_Contributions[[#This Row],[اسم المشروع]], Tbl_Projects[اسم المشروع], 0)) * Tbl_Contributions[[#This Row],[نسبة مساهمته]], 0) -> -428733.33 | I4: =IF(AND(ISNUMBER(Tbl_Contributions[[#This Row],[نسبة الإدارة الخاصة به]]), Tbl_Contributions[[#This Row],[حصة الربح قبل الإدارة]]>0), Tbl_Contributions[[#This Row],[حصة الربح قبل الإدارة]] * Tbl_Contributions[[#This Row],[نسبة الإدارة الخاصة به]], 0) -> 0 | J4: =Tbl_Contributions[[#This Row],[حصة الربح قبل الإدارة]] - Tbl_Contributions[[#This Row],[نصيب الإدارة]] -> -428733.33 | K4: =Tbl_Contributions[[#This Row],[رأس مال المساهم]] + Tbl_Contributions[[#This Row],[صافي ربح المساهم]] -> 571266.67 | L4: =SUMIFS(Tbl_Distributions[المبلغ], Tbl_Distributions[المشروع المصدر], Tbl_Contributions[[#This Row],[اسم المشروع]], Tbl_Distributions[المساهم], Tbl_Contributions[[#This Row],[اسم المساهم]], Tbl_Distributions[نوع العملية], "<>تحويل بين المشاريع", Tbl_Distributions[نوع العملية], "<>مسحوب للإدارة") -> 500000 | M4: =SUMIFS(Tbl_Distributions[المبلغ], Tbl_Distributions[المشروع المصدر], Tbl_Contributions[[#This Row],[اسم المشروع]], Tbl_Distributions[المساهم], Tbl_Contributions[[#This Row],[اسم المساهم]], Tbl_Distributions[نوع العملية], "مسحوب للإدارة") -> 0 | N4: =Tbl_Contributions[[#This Row],[إجمالي المستحق للمساهم]] - Tbl_Contributions[[#This Row],[المسحوبات (تتضمن رد رأس المال والأرباح)]] -> 71266.667 | O4: =IF(ISBLANK(Tbl_Contributions[[#This Row],[نسبة الإدارة الخاصة به]]), "تنبيه: نسبة الإدارة غير مسجلة", "مكتمل") -> مكتمل
A5: =IFERROR(INDEX([1]!Tbl_Projects[كود المشروع], MATCH([1]!Tbl_Contributions[[#This Row],[اسم المشروع]], [1]!Tbl_Projects[اسم المشروع], 0)), "") | B5: 8842 | C5: =IFERROR(INDEX([1]!Tbl_Investors[كود المساهم], MATCH([1]!Tbl_Contributions[[#This Row],[اسم المساهم]], [1]!Tbl_Investors[اسم المساهم], 0)), "") | D5: مايز محمد | E5: 2000000 | F5: =IF(SUMIFS(Tbl_Contributions[رأس مال المساهم], Tbl_Contributions[اسم المشروع], Tbl_Contributions[[#This Row],[اسم المشروع]])=0, 0, Tbl_Contributions[[#This Row],[رأس مال المساهم]]/SUMIFS(Tbl_Contributions[رأس مال المساهم], Tbl_Contributions[اسم المشروع], Tbl_Contributions[[#This Row],[اسم المشروع]])) -> 0.13333333 | G5: 0.2 | H5: =IFERROR(INDEX(Tbl_Projects[صافي الربح], MATCH(Tbl_Contributions[[#This Row],[اسم المشروع]], Tbl_Projects[اسم المشروع], 0)) * Tbl_Contributions[[#This Row],[نسبة مساهمته]], 0) -> -857466.67 | I5: =IF(AND(ISNUMBER(Tbl_Contributions[[#This Row],[نسبة الإدارة الخاصة به]]), Tbl_Contributions[[#This Row],[حصة الربح قبل الإدارة]]>0), Tbl_Contributions[[#This Row],[حصة الربح قبل الإدارة]] * Tbl_Contributions[[#This Row],[نسبة الإدارة الخاصة به]], 0) -> 0 | J5: =Tbl_Contributions[[#This Row],[حصة الربح قبل الإدارة]] - Tbl_Contributions[[#This Row],[نصيب الإدارة]] -> -857466.67 | K5: =Tbl_Contributions[[#This Row],[رأس مال المساهم]] + Tbl_Contributions[[#This Row],[صافي ربح المساهم]] -> 1142533.3 | L5: =SUMIFS(Tbl_Distributions[المبلغ], Tbl_Distributions[المشروع المصدر], Tbl_Contributions[[#This Row],[اسم المشروع]], Tbl_Distributions[المساهم], Tbl_Contributions[[#This Row],[اسم المساهم]], Tbl_Distributions[نوع العملية], "<>تحويل بين المشاريع", Tbl_Distributions[نوع العملية], "<>مسحوب للإدارة") -> 0 | M5: =SUMIFS(Tbl_Distributions[المبلغ], Tbl_Distributions[المشروع المصدر], Tbl_Contributions[[#This Row],[اسم المشروع]], Tbl_Distributions[المساهم], Tbl_Contributions[[#This Row],[اسم المساهم]], Tbl_Distributions[نوع العملية], "مسحوب للإدارة") -> 0 | N5: =Tbl_Contributions[[#This Row],[إجمالي المستحق للمساهم]] - Tbl_Contributions[[#This Row],[المسحوبات (تتضمن رد رأس المال والأرباح)]] -> 1142533.3 | O5: =IF(ISBLANK(Tbl_Contributions[[#This Row],[نسبة الإدارة الخاصة به]]), "تنبيه: نسبة الإدارة غير مسجلة", "مكتمل") -> مكتمل
A6: =IFERROR(INDEX([1]!Tbl_Projects[كود المشروع], MATCH([1]!Tbl_Contributions[[#This Row],[اسم المشروع]], [1]!Tbl_Projects[اسم المشروع], 0)), "") | B6: 8842 | C6: =IFERROR(INDEX([1]!Tbl_Investors[كود المساهم], MATCH([1]!Tbl_Contributions[[#This Row],[اسم المساهم]], [1]!Tbl_Investors[اسم المساهم], 0)), "") | D6: زكريا على | E6: 4500000 | F6: =IF(SUMIFS(Tbl_Contributions[رأس مال المساهم], Tbl_Contributions[اسم المشروع], Tbl_Contributions[[#This Row],[اسم المشروع]])=0, 0, Tbl_Contributions[[#This Row],[رأس مال المساهم]]/SUMIFS(Tbl_Contributions[رأس مال المساهم], Tbl_Contributions[اسم المشروع], Tbl_Contributions[[#This Row],[اسم المشروع]])) -> 0.3 | G6: 0.2 | H6: =IFERROR(INDEX(Tbl_Projects[صافي الربح], MATCH(Tbl_Contributions[[#This Row],[اسم المشروع]], Tbl_Projects[اسم المشروع], 0)) * Tbl_Contributions[[#This Row],[نسبة مساهمته]], 0) -> -1929300 | I6: =IF(AND(ISNUMBER(Tbl_Contributions[[#This Row],[نسبة الإدارة الخاصة به]]), Tbl_Contributions[[#This Row],[حصة الربح قبل الإدارة]]>0), Tbl_Contributions[[#This Row],[حصة الربح قبل الإدارة]] * Tbl_Contributions[[#This Row],[نسبة الإدارة الخاصة به]], 0) -> 0 | J6: =Tbl_Contributions[[#This Row],[حصة الربح قبل الإدارة]] - Tbl_Contributions[[#This Row],[نصيب الإدارة]] -> -1929300 | K6: =Tbl_Contributions[[#This Row],[رأس مال المساهم]] + Tbl_Contributions[[#This Row],[صافي ربح المساهم]] -> 2570700 | L6: =SUMIFS(Tbl_Distributions[المبلغ], Tbl_Distributions[المشروع المصدر], Tbl_Contributions[[#This Row],[اسم المشروع]], Tbl_Distributions[المساهم], Tbl_Contributions[[#This Row],[اسم المساهم]], Tbl_Distributions[نوع العملية], "<>تحويل بين المشاريع", Tbl_Distributions[نوع العملية], "<>مسحوب للإدارة") -> 0 | M6: =SUMIFS(Tbl_Distributions[المبلغ], Tbl_Distributions[المشروع المصدر], Tbl_Contributions[[#This Row],[اسم المشروع]], Tbl_Distributions[المساهم], Tbl_Contributions[[#This Row],[اسم المساهم]], Tbl_Distributions[نوع العملية], "مسحوب للإدارة") -> 0 | N6: =Tbl_Contributions[[#This Row],[إجمالي المستحق للمساهم]] - Tbl_Contributions[[#This Row],[المسحوبات (تتضمن رد رأس المال والأرباح)]] -> 2570700 | O6: =IF(ISBLANK(Tbl_Contributions[[#This Row],[نسبة الإدارة الخاصة به]]), "تنبيه: نسبة الإدارة غير مسجلة", "مكتمل") -> مكتمل
A7: =IFERROR(INDEX([1]!Tbl_Projects[كود المشروع], MATCH([1]!Tbl_Contributions[[#This Row],[اسم المشروع]], [1]!Tbl_Projects[اسم المشروع], 0)), "") | B7: 8842 | C7: =IFERROR(INDEX([1]!Tbl_Investors[كود المساهم], MATCH([1]!Tbl_Contributions[[#This Row],[اسم المساهم]], [1]!Tbl_Investors[اسم المساهم], 0)), "") | D7: رمضان رجب | E7: 370000 | F7: =IF(SUMIFS(Tbl_Contributions[رأس مال المساهم], Tbl_Contributions[اسم المشروع], Tbl_Contributions[[#This Row],[اسم المشروع]])=0, 0, Tbl_Contributions[[#This Row],[رأس مال المساهم]]/SUMIFS(Tbl_Contributions[رأس مال المساهم], Tbl_Contributions[اسم المشروع], Tbl_Contributions[[#This Row],[اسم المشروع]])) -> 0.024666667 | G7: 0.2 | H7: =IFERROR(INDEX(Tbl_Projects[صافي الربح], MATCH(Tbl_Contributions[[#This Row],[اسم المشروع]], Tbl_Projects[اسم المشروع], 0)) * Tbl_Contributions[[#This Row],[نسبة مساهمته]], 0) -> -158631.33 | I7: =IF(AND(ISNUMBER(Tbl_Contributions[[#This Row],[نسبة الإدارة الخاصة به]]), Tbl_Contributions[[#This Row],[حصة الربح قبل الإدارة]]>0), Tbl_Contributions[[#This Row],[حصة الربح قبل الإدارة]] * Tbl_Contributions[[#This Row],[نسبة الإدارة الخاصة به]], 0) -> 0 | J7: =Tbl_Contributions[[#This Row],[حصة الربح قبل الإدارة]] - Tbl_Contributions[[#This Row],[نصيب الإدارة]] -> -158631.33 | K7: =Tbl_Contributions[[#This Row],[رأس مال المساهم]] + Tbl_Contributions[[#This Row],[صافي ربح المساهم]] -> 211368.67 | L7: =SUMIFS(Tbl_Distributions[المبلغ], Tbl_Distributions[المشروع المصدر], Tbl_Contributions[[#This Row],[اسم المشروع]], Tbl_Distributions[المساهم], Tbl_Contributions[[#This Row],[اسم المساهم]], Tbl_Distributions[نوع العملية], "<>تحويل بين المشاريع", Tbl_Distributions[نوع العملية], "<>مسحوب للإدارة") -> 0 | M7: =SUMIFS(Tbl_Distributions[المبلغ], Tbl_Distributions[المشروع المصدر], Tbl_Contributions[[#This Row],[اسم المشروع]], Tbl_Distributions[المساهم], Tbl_Contributions[[#This Row],[اسم المساهم]], Tbl_Distributions[نوع العملية], "مسحوب للإدارة") -> 0 | N7: =Tbl_Contributions[[#This Row],[إجمالي المستحق للمساهم]] - Tbl_Contributions[[#This Row],[المسحوبات (تتضمن رد رأس المال والأرباح)]] -> 211368.67 | O7: =IF(ISBLANK(Tbl_Contributions[[#This Row],[نسبة الإدارة الخاصة به]]), "تنبيه: نسبة الإدارة غير مسجلة", "مكتمل") -> مكتمل
A8: =IFERROR(INDEX([1]!Tbl_Projects[كود المشروع], MATCH([1]!Tbl_Contributions[[#This Row],[اسم المشروع]], [1]!Tbl_Projects[اسم المشروع], 0)), "") | B8: 8842 | C8: =IFERROR(INDEX([1]!Tbl_Investors[كود المساهم], MATCH([1]!Tbl_Contributions[[#This Row],[اسم المساهم]], [1]!Tbl_Investors[اسم المساهم], 0)), "") | D8: اشرف ابراهيم | E8: 125000 | F8: =IF(SUMIFS(Tbl_Contributions[رأس مال المساهم], Tbl_Contributions[اسم المشروع], Tbl_Contributions[[#This Row],[اسم المشروع]])=0, 0, Tbl_Contributions[[#This Row],[رأس مال المساهم]]/SUMIFS(Tbl_Contributions[رأس مال المساهم], Tbl_Contributions[اسم المشروع], Tbl_Contributions[[#This Row],[اسم المشروع]])) -> 0.0083333333 | G8: 0.2 | H8: =IFERROR(INDEX(Tbl_Projects[صافي الربح], MATCH(Tbl_Contributions[[#This Row],[اسم المشروع]], Tbl_Projects[اسم المشروع], 0)) * Tbl_Contributions[[#This Row],[نسبة مساهمته]], 0) -> -53591.667 | I8: =IF(AND(ISNUMBER(Tbl_Contributions[[#This Row],[نسبة الإدارة الخاصة به]]), Tbl_Contributions[[#This Row],[حصة الربح قبل الإدارة]]>0), Tbl_Contributions[[#This Row],[حصة الربح قبل الإدارة]] * Tbl_Contributions[[#This Row],[نسبة الإدارة الخاصة به]], 0) -> 0 | J8: =Tbl_Contributions[[#This Row],[حصة الربح قبل الإدارة]] - Tbl_Contributions[[#This Row],[نصيب الإدارة]] -> -53591.667 | K8: =Tbl_Contributions[[#This Row],[رأس مال المساهم]] + Tbl_Contributions[[#This Row],[صافي ربح المساهم]] -> 71408.333 | L8: =SUMIFS(Tbl_Distributions[المبلغ], Tbl_Distributions[المشروع المصدر], Tbl_Contributions[[#This Row],[اسم المشروع]], Tbl_Distributions[المساهم], Tbl_Contributions[[#This Row],[اسم المساهم]], Tbl_Distributions[نوع العملية], "<>تحويل بين المشاريع", Tbl_Distributions[نوع العملية], "<>مسحوب للإدارة") -> 0 | M8: =SUMIFS(Tbl_Distributions[المبلغ], Tbl_Distributions[المشروع المصدر], Tbl_Contributions[[#This Row],[اسم المشروع]], Tbl_Distributions[المساهم], Tbl_Contributions[[#This Row],[اسم المساهم]], Tbl_Distributions[نوع العملية], "مسحوب للإدارة") -> 0 | N8: =Tbl_Contributions[[#This Row],[إجمالي المستحق للمساهم]] - Tbl_Contributions[[#This Row],[المسحوبات (تتضمن رد رأس المال والأرباح)]] -> 71408.333 | O8: =IF(ISBLANK(Tbl_Contributions[[#This Row],[نسبة الإدارة الخاصة به]]), "تنبيه: نسبة الإدارة غير مسجلة", "مكتمل") -> مكتمل
A9: =IFERROR(INDEX([1]!Tbl_Projects[كود المشروع], MATCH([1]!Tbl_Contributions[[#This Row],[اسم المشروع]], [1]!Tbl_Projects[اسم المشروع], 0)), "") | B9: 8842 | C9: =IFERROR(INDEX([1]!Tbl_Investors[كود المساهم], MATCH([1]!Tbl_Contributions[[#This Row],[اسم المساهم]], [1]!Tbl_Investors[اسم المساهم], 0)), "") | D9: على ممدوح | E9: 840000 | F9: =IF(SUMIFS(Tbl_Contributions[رأس مال المساهم], Tbl_Contributions[اسم المشروع], Tbl_Contributions[[#This Row],[اسم المشروع]])=0, 0, Tbl_Contributions[[#This Row],[رأس مال المساهم]]/SUMIFS(Tbl_Contributions[رأس مال المساهم], Tbl_Contributions[اسم المشروع], Tbl_Contributions[[#This Row],[اسم المشروع]])) -> 0.056 | G9: 0.2 | H9: =IFERROR(INDEX(Tbl_Projects[صافي الربح], MATCH(Tbl_Contributions[[#This Row],[اسم المشروع]], Tbl_Projects[اسم المشروع], 0)) * Tbl_Contributions[[#This Row],[نسبة مساهمته]], 0) -> -360136 | I9: =IF(AND(ISNUMBER(Tbl_Contributions[[#This Row],[نسبة الإدارة الخاصة به]]), Tbl_Contributions[[#This Row],[حصة الربح قبل الإدارة]]>0), Tbl_Contributions[[#This Row],[حصة الربح قبل الإدارة]] * Tbl_Contributions[[#This Row],[نسبة الإدارة الخاصة به]], 0) -> 0 | J9: =Tbl_Contributions[[#This Row],[حصة الربح قبل الإدارة]] - Tbl_Contributions[[#This Row],[نصيب الإدارة]] -> -360136 | K9: =Tbl_Contributions[[#This Row],[رأس مال المساهم]] + Tbl_Contributions[[#This Row],[صافي ربح المساهم]] -> 479864 | L9: =SUMIFS(Tbl_Distributions[المبلغ], Tbl_Distributions[المشروع المصدر], Tbl_Contributions[[#This Row],[اسم المشروع]], Tbl_Distributions[المساهم], Tbl_Contributions[[#This Row],[اسم المساهم]], Tbl_Distributions[نوع العملية], "<>تحويل بين المشاريع", Tbl_Distributions[نوع العملية], "<>مسحوب للإدارة") -> 0 | M9: =SUMIFS(Tbl_Distributions[المبلغ], Tbl_Distributions[المشروع المصدر], Tbl_Contributions[[#This Row],[اسم المشروع]], Tbl_Distributions[المساهم], Tbl_Contributions[[#This Row],[اسم المساهم]], Tbl_Distributions[نوع العملية], "مسحوب للإدارة") -> 0 | N9: =Tbl_Contributions[[#This Row],[إجمالي المستحق للمساهم]] - Tbl_Contributions[[#This Row],[المسحوبات (تتضمن رد رأس المال والأرباح)]] -> 479864 | O9: =IF(ISBLANK(Tbl_Contributions[[#This Row],[نسبة الإدارة الخاصة به]]), "تنبيه: نسبة الإدارة غير مسجلة", "مكتمل") -> مكتمل
A10: =IFERROR(INDEX([1]!Tbl_Projects[كود المشروع], MATCH([1]!Tbl_Contributions[[#This Row],[اسم المشروع]], [1]!Tbl_Projects[اسم المشروع], 0)), "") | B10: 8842 | C10: =IFERROR(INDEX([1]!Tbl_Investors[كود المساهم], MATCH([1]!Tbl_Contributions[[#This Row],[اسم المساهم]], [1]!Tbl_Investors[اسم المساهم], 0)), "") | D10: عمر صلاح | E10: 325000 | F10: =IF(SUMIFS(Tbl_Contributions[رأس مال المساهم], Tbl_Contributions[اسم المشروع], Tbl_Contributions[[#This Row],[اسم المشروع]])=0, 0, Tbl_Contributions[[#This Row],[رأس مال المساهم]]/SUMIFS(Tbl_Contributions[رأس مال المساهم], Tbl_Contributions[اسم المشروع], Tbl_Contributions[[#This Row],[اسم المشروع]])) -> 0.021666667 | G10: 0.2 | H10: =IFERROR(INDEX(Tbl_Projects[صافي الربح], MATCH(Tbl_Contributions[[#This Row],[اسم المشروع]], Tbl_Projects[اسم المشروع], 0)) * Tbl_Contributions[[#This Row],[نسبة مساهمته]], 0) -> -139338.33 | I10: =IF(AND(ISNUMBER(Tbl_Contributions[[#This Row],[نسبة الإدارة الخاصة به]]), Tbl_Contributions[[#This Row],[حصة الربح قبل الإدارة]]>0), Tbl_Contributions[[#This Row],[حصة الربح قبل الإدارة]] * Tbl_Contributions[[#This Row],[نسبة الإدارة الخاصة به]], 0) -> 0 | J10: =Tbl_Contributions[[#This Row],[حصة الربح قبل الإدارة]] - Tbl_Contributions[[#This Row],[نصيب الإدارة]] -> -139338.33 | K10: =Tbl_Contributions[[#This Row],[رأس مال المساهم]] + Tbl_Contributions[[#This Row],[صافي ربح المساهم]] -> 185661.67 | L10: =SUMIFS(Tbl_Distributions[المبلغ], Tbl_Distributions[المشروع المصدر], Tbl_Contributions[[#This Row],[اسم المشروع]], Tbl_Distributions[المساهم], Tbl_Contributions[[#This Row],[اسم المساهم]], Tbl_Distributions[نوع العملية], "<>تحويل بين المشاريع", Tbl_Distributions[نوع العملية], "<>مسحوب للإدارة") -> 0 | M10: =SUMIFS(Tbl_Distributions[المبلغ], Tbl_Distributions[المشروع المصدر], Tbl_Contributions[[#This Row],[اسم المشروع]], Tbl_Distributions[المساهم], Tbl_Contributions[[#This Row],[اسم المساهم]], Tbl_Distributions[نوع العملية], "مسحوب للإدارة") -> 0 | N10: =Tbl_Contributions[[#This Row],[إجمالي المستحق للمساهم]] - Tbl_Contributions[[#This Row],[المسحوبات (تتضمن رد رأس المال والأرباح)]] -> 185661.67 | O10: =IF(ISBLANK(Tbl_Contributions[[#This Row],[نسبة الإدارة الخاصة به]]), "تنبيه: نسبة الإدارة غير مسجلة", "مكتمل") -> مكتمل
A11: =IFERROR(INDEX([1]!Tbl_Projects[كود المشروع], MATCH([1]!Tbl_Contributions[[#This Row],[اسم المشروع]], [1]!Tbl_Projects[اسم المشروع], 0)), "") | B11: 8842 | C11: =IFERROR(INDEX([1]!Tbl_Investors[كود المساهم], MATCH([1]!Tbl_Contributions[[#This Row],[اسم المساهم]], [1]!Tbl_Investors[اسم المساهم], 0)), "") | D11: جمعه خلف | E11: 245000 | F11: =IF(SUMIFS(Tbl_Contributions[رأس مال المساهم], Tbl_Contributions[اسم المشروع], Tbl_Contributions[[#This Row],[اسم المشروع]])=0, 0, Tbl_Contributions[[#This Row],[رأس مال المساهم]]/SUMIFS(Tbl_Contributions[رأس مال المساهم], Tbl_Contributions[اسم المشروع], Tbl_Contributions[[#This Row],[اسم المشروع]])) -> 0.016333333 | G11: 0.2 | H11: =IFERROR(INDEX(Tbl_Projects[صافي الربح], MATCH(Tbl_Contributions[[#This Row],[اسم المشروع]], Tbl_Projects[اسم المشروع], 0)) * Tbl_Contributions[[#This Row],[نسبة مساهمته]], 0) -> -105039.67 | I11: =IF(AND(ISNUMBER(Tbl_Contributions[[#This Row],[نسبة الإدارة الخاصة به]]), Tbl_Contributions[[#This Row],[حصة الربح قبل الإدارة]]>0), Tbl_Contributions[[#This Row],[حصة الربح قبل الإدارة]] * Tbl_Contributions[[#This Row],[نسبة الإدارة الخاصة به]], 0) -> 0 | J11: =Tbl_Contributions[[#This Row],[حصة الربح قبل الإدارة]] - Tbl_Contributions[[#This Row],[نصيب الإدارة]] -> -105039.67 | K11: =Tbl_Contributions[[#This Row],[رأس مال المساهم]] + Tbl_Contributions[[#This Row],[صافي ربح المساهم]] -> 139960.33 | L11: =SUMIFS(Tbl_Distributions[المبلغ], Tbl_Distributions[المشروع المصدر], Tbl_Contributions[[#This Row],[اسم المشروع]], Tbl_Distributions[المساهم], Tbl_Contributions[[#This Row],[اسم المساهم]], Tbl_Distributions[نوع العملية], "<>تحويل بين المشاريع", Tbl_Distributions[نوع العملية], "<>مسحوب للإدارة") -> 0 | M11: =SUMIFS(Tbl_Distributions[المبلغ], Tbl_Distributions[المشروع المصدر], Tbl_Contributions[[#This Row],[اسم المشروع]], Tbl_Distributions[المساهم], Tbl_Contributions[[#This Row],[اسم المساهم]], Tbl_Distributions[نوع العملية], "مسحوب للإدارة") -> 0 | N11: =Tbl_Contributions[[#This Row],[إجمالي المستحق للمساهم]] - Tbl_Contributions[[#This Row],[المسحوبات (تتضمن رد رأس المال والأرباح)]] -> 139960.33 | O11: =IF(ISBLANK(Tbl_Contributions[[#This Row],[نسبة الإدارة الخاصة به]]), "تنبيه: نسبة الإدارة غير مسجلة", "مكتمل") -> مكتمل
A12: =IFERROR(INDEX([1]!Tbl_Projects[كود المشروع], MATCH([1]!Tbl_Contributions[[#This Row],[اسم المشروع]], [1]!Tbl_Projects[اسم المشروع], 0)), "") | B12: 8842 | C12: =IFERROR(INDEX([1]!Tbl_Investors[كود المساهم], MATCH([1]!Tbl_Contributions[[#This Row],[اسم المساهم]], [1]!Tbl_Investors[اسم المساهم], 0)), "") | D12: محمد ناجى | E12: 1000000 | F12: =IF(SUMIFS(Tbl_Contributions[رأس مال المساهم], Tbl_Contributions[اسم المشروع], Tbl_Contributions[[#This Row],[اسم المشروع]])=0, 0, Tbl_Contributions[[#This Row],[رأس مال المساهم]]/SUMIFS(Tbl_Contributions[رأس مال المساهم], Tbl_Contributions[اسم المشروع], Tbl_Contributions[[#This Row],[اسم المشروع]])) -> 0.066666667 | G12: 0.2 | H12: =IFERROR(INDEX(Tbl_Projects[صافي الربح], MATCH(Tbl_Contributions[[#This Row],[اسم المشروع]], Tbl_Projects[اسم المشروع], 0)) * Tbl_Contributions[[#This Row],[نسبة مساهمته]], 0) -> -428733.33 | I12: =IF(AND(ISNUMBER(Tbl_Contributions[[#This Row],[نسبة الإدارة الخاصة به]]), Tbl_Contributions[[#This Row],[حصة الربح قبل الإدارة]]>0), Tbl_Contributions[[#This Row],[حصة الربح قبل الإدارة]] * Tbl_Contributions[[#This Row],[نسبة الإدارة الخاصة به]], 0) -> 0 | J12: =Tbl_Contributions[[#This Row],[حصة الربح قبل الإدارة]] - Tbl_Contributions[[#This Row],[نصيب الإدارة]] -> -428733.33 | K12: =Tbl_Contributions[[#This Row],[رأس مال المساهم]] + Tbl_Contributions[[#This Row],[صافي ربح المساهم]] -> 571266.67 | L12: =SUMIFS(Tbl_Distributions[المبلغ], Tbl_Distributions[المشروع المصدر], Tbl_Contributions[[#This Row],[اسم المشروع]], Tbl_Distributions[المساهم], Tbl_Contributions[[#This Row],[اسم المساهم]], Tbl_Distributions[نوع العملية], "<>تحويل بين المشاريع", Tbl_Distributions[نوع العملية], "<>مسحوب للإدارة") -> 0 | M12: =SUMIFS(Tbl_Distributions[المبلغ], Tbl_Distributions[المشروع المصدر], Tbl_Contributions[[#This Row],[اسم المشروع]], Tbl_Distributions[المساهم], Tbl_Contributions[[#This Row],[اسم المساهم]], Tbl_Distributions[نوع العملية], "مسحوب للإدارة") -> 0 | N12: =Tbl_Contributions[[#This Row],[إجمالي المستحق للمساهم]] - Tbl_Contributions[[#This Row],[المسحوبات (تتضمن رد رأس المال والأرباح)]] -> 571266.67 | O12: =IF(ISBLANK(Tbl_Contributions[[#This Row],[نسبة الإدارة الخاصة به]]), "تنبيه: نسبة الإدارة غير مسجلة", "مكتمل") -> مكتمل
A13: =IFERROR(INDEX([1]!Tbl_Projects[كود المشروع], MATCH([1]!Tbl_Contributions[[#This Row],[اسم المشروع]], [1]!Tbl_Projects[اسم المشروع], 0)), "") | B13: 8842 | C13: =IFERROR(INDEX([1]!Tbl_Investors[كود المساهم], MATCH([1]!Tbl_Contributions[[#This Row],[اسم المساهم]], [1]!Tbl_Investors[اسم المساهم], 0)), "") | D13: عماد تقى نقى | E13: 450000 | F13: =IF(SUMIFS(Tbl_Contributions[رأس مال المساهم], Tbl_Contributions[اسم المشروع], Tbl_Contributions[[#This Row],[اسم المشروع]])=0, 0, Tbl_Contributions[[#This Row],[رأس مال المساهم]]/SUMIFS(Tbl_Contributions[رأس مال المساهم], Tbl_Contributions[اسم المشروع], Tbl_Contributions[[#This Row],[اسم المشروع]])) -> 0.03 | G13: 0.2 | H13: =IFERROR(INDEX(Tbl_Projects[صافي الربح], MATCH(Tbl_Contributions[[#This Row],[اسم المشروع]], Tbl_Projects[اسم المشروع], 0)) * Tbl_Contributions[[#This Row],[نسبة مساهمته]], 0) -> -192930 | I13: =IF(AND(ISNUMBER(Tbl_Contributions[[#This Row],[نسبة الإدارة الخاصة به]]), Tbl_Contributions[[#This Row],[حصة الربح قبل الإدارة]]>0), Tbl_Contributions[[#This Row],[حصة الربح قبل الإدارة]] * Tbl_Contributions[[#This Row],[نسبة الإدارة الخاصة به]], 0) -> 0 | J13: =Tbl_Contributions[[#This Row],[حصة الربح قبل الإدارة]] - Tbl_Contributions[[#This Row],[نصيب الإدارة]] -> -192930 | K13: =Tbl_Contributions[[#This Row],[رأس مال المساهم]] + Tbl_Contributions[[#This Row],[صافي ربح المساهم]] -> 257070 | L13: =SUMIFS(Tbl_Distributions[المبلغ], Tbl_Distributions[المشروع المصدر], Tbl_Contributions[[#This Row],[اسم المشروع]], Tbl_Distributions[المساهم], Tbl_Contributions[[#This Row],[اسم المساهم]], Tbl_Distributions[نوع العملية], "<>تحويل بين المشاريع", Tbl_Distributions[نوع العملية], "<>مسحوب للإدارة") -> 0 | M13: =SUMIFS(Tbl_Distributions[المبلغ], Tbl_Distributions[المشروع المصدر], Tbl_Contributions[[#This Row],[اسم المشروع]], Tbl_Distributions[المساهم], Tbl_Contributions[[#This Row],[اسم المساهم]], Tbl_Distributions[نوع العملية], "مسحوب للإدارة") -> 0 | N13: =Tbl_Contributions[[#This Row],[إجمالي المستحق للمساهم]] - Tbl_Contributions[[#This Row],[المسحوبات (تتضمن رد رأس المال والأرباح)]] -> 257070 | O13: =IF(ISBLANK(Tbl_Contributions[[#This Row],[نسبة الإدارة الخاصة به]]), "تنبيه: نسبة الإدارة غير مسجلة", "مكتمل") -> مكتمل
A14: =IFERROR(INDEX([1]!Tbl_Projects[كود المشروع], MATCH([1]!Tbl_Contributions[[#This Row],[اسم المشروع]], [1]!Tbl_Projects[اسم المشروع], 0)), "") | B14: 8842 | C14: =IFERROR(INDEX([1]!Tbl_Investors[كود المساهم], MATCH([1]!Tbl_Contributions[[#This Row],[اسم المساهم]], [1]!Tbl_Investors[اسم المساهم], 0)), "") | D14: امدحت | E14: 750000 | F14: =IF(SUMIFS(Tbl_Contributions[رأس مال المساهم], Tbl_Contributions[اسم المشروع], Tbl_Contributions[[#This Row],[اسم المشروع]])=0, 0, Tbl_Contributions[[#This Row],[رأس مال المساهم]]/SUMIFS(Tbl_Contributions[رأس مال المساهم], Tbl_Contributions[اسم المشروع], Tbl_Contributions[[#This Row],[اسم المشروع]])) -> 0.05 | G14: 0.2 | H14: =IFERROR(INDEX(Tbl_Projects[صافي الربح], MATCH(Tbl_Contributions[[#This Row],[اسم المشروع]], Tbl_Projects[اسم المشروع], 0)) * Tbl_Contributions[[#This Row],[نسبة مساهمته]], 0) -> -321550 | I14: =IF(AND(ISNUMBER(Tbl_Contributions[[#This Row],[نسبة الإدارة الخاصة به]]), Tbl_Contributions[[#This Row],[حصة الربح قبل الإدارة]]>0), Tbl_Contributions[[#This Row],[حصة الربح قبل الإدارة]] * Tbl_Contributions[[#This Row],[نسبة الإدارة الخاصة به]], 0) -> 0 | J14: =Tbl_Contributions[[#This Row],[حصة الربح قبل الإدارة]] - Tbl_Contributions[[#This Row],[نصيب الإدارة]] -> -321550 | K14: =Tbl_Contributions[[#This Row],[رأس مال المساهم]] + Tbl_Contributions[[#This Row],[صافي ربح المساهم]] -> 428450 | L14: =SUMIFS(Tbl_Distributions[المبلغ], Tbl_Distributions[المشروع المصدر], Tbl_Contributions[[#This Row],[اسم المشروع]], Tbl_Distributions[المساهم], Tbl_Contributions[[#This Row],[اسم المساهم]], Tbl_Distributions[نوع العملية], "<>تحويل بين المشاريع", Tbl_Distributions[نوع العملية], "<>مسحوب للإدارة") -> 0 | M14: =SUMIFS(Tbl_Distributions[المبلغ], Tbl_Distributions[المشروع المصدر], Tbl_Contributions[[#This Row],[اسم المشروع]], Tbl_Distributions[المساهم], Tbl_Contributions[[#This Row],[اسم المساهم]], Tbl_Distributions[نوع العملية], "مسحوب للإدارة") -> 0 | N14: =Tbl_Contributions[[#This Row],[إجمالي المستحق للمساهم]] - Tbl_Contributions[[#This Row],[المسحوبات (تتضمن رد رأس المال والأرباح)]] -> 428450 | O14: =IF(ISBLANK(Tbl_Contributions[[#This Row],[نسبة الإدارة الخاصة به]]), "تنبيه: نسبة الإدارة غير مسجلة", "مكتمل") -> مكتمل
... A42: =IFERROR(INDEX([1]!Tbl_Projects[كود المشروع], MATCH([1]!Tbl_Contributions[[#This Row],[اسم المشروع]], [1]!Tbl_Projects[اسم المشروع], 0)), "") | B42: خلف قطعة بلال قطعه 12 | C42: =IFERROR(INDEX([1]!Tbl_Investors[كود المساهم], MATCH([1]!Tbl_Contributions[[#This Row],[اسم المساهم]], [1]!Tbl_Investors[اسم المساهم], 0)), "") | D42: امدحت | E42: 100000 | F42: =IF(SUMIFS(Tbl_Contributions[رأس مال المساهم], Tbl_Contributions[اسم المشروع], Tbl_Contributions[[#This Row],[اسم المشروع]])=0, 0, Tbl_Contributions[[#This Row],[رأس مال المساهم]]/SUMIFS(Tbl_Contributions[رأس مال المساهم], Tbl_Contributions[اسم المشروع], Tbl_Contributions[[#This Row],[اسم المشروع]])) -> 0.02 | G42: 0.2 | H42: =IFERROR(INDEX(Tbl_Projects[صافي الربح], MATCH(Tbl_Contributions[[#This Row],[اسم المشروع]], Tbl_Projects[اسم المشروع], 0)) * Tbl_Contributions[[#This Row],[نسبة مساهمته]], 0) -> -100000 | I42: =IF(AND(ISNUMBER(Tbl_Contributions[[#This Row],[نسبة الإدارة الخاصة به]]), Tbl_Contributions[[#This Row],[حصة الربح قبل الإدارة]]>0), Tbl_Contributions[[#This Row],[حصة الربح قبل الإدارة]] * Tbl_Contributions[[#This Row],[نسبة الإدارة الخاصة به]], 0) -> 0 | J42: =Tbl_Contributions[[#This Row],[حصة الربح قبل الإدارة]] - Tbl_Contributions[[#This Row],[نصيب الإدارة]] -> -100000 | K42: =Tbl_Contributions[[#This Row],[رأس مال المساهم]] + Tbl_Contributions[[#This Row],[صافي ربح المساهم]] -> 0 | L42: =SUMIFS(Tbl_Distributions[المبلغ], Tbl_Distributions[المشروع المصدر], Tbl_Contributions[[#This Row],[اسم المشروع]], Tbl_Distributions[المساهم], Tbl_Contributions[[#This Row],[اسم المساهم]], Tbl_Distributions[نوع العملية], "<>تحويل بين المشاريع", Tbl_Distributions[نوع العملية], "<>مسحوب للإدارة") -> 0 | M42: =SUMIFS(Tbl_Distributions[المبلغ], Tbl_Distributions[المشروع المصدر], Tbl_Contributions[[#This Row],[اسم المشروع]], Tbl_Distributions[المساهم], Tbl_Contributions[[#This Row],[اسم المساهم]], Tbl_Distributions[نوع العملية], "مسحوب للإدارة") -> 0 | N42: =Tbl_Contributions[[#This Row],[إجمالي المستحق للمساهم]] - Tbl_Contributions[[#This Row],[المسحوبات (تتضمن رد رأس المال والأرباح)]] -> 0 | O42: =IF(ISBLANK(Tbl_Contributions[[#This Row],[نسبة الإدارة الخاصة به]]), "تنبيه: نسبة الإدارة غير مسجلة", "مكتمل") -> مكتمل
A43: =IFERROR(INDEX([1]!Tbl_Projects[كود المشروع], MATCH([1]!Tbl_Contributions[[#This Row],[اسم المشروع]], [1]!Tbl_Projects[اسم المشروع], 0)), "") | B43: شقة الاكاديمية | D43: مايز محمد | E43: 200000 | F43: =IF(SUMIFS(Tbl_Contributions[رأس مال المساهم], Tbl_Contributions[اسم المشروع], Tbl_Contributions[[#This Row],[اسم المشروع]])=0, 0, Tbl_Contributions[[#This Row],[رأس مال المساهم]]/SUMIFS(Tbl_Contributions[رأس مال المساهم], Tbl_Contributions[اسم المشروع], Tbl_Contributions[[#This Row],[اسم المشروع]])) -> 0.064516129 | G43: 0.2 | H43: =IFERROR(INDEX(Tbl_Projects[صافي الربح], MATCH(Tbl_Contributions[[#This Row],[اسم المشروع]], Tbl_Projects[اسم المشروع], 0)) * Tbl_Contributions[[#This Row],[نسبة مساهمته]], 0) -> 46451.613 | I43: =IF(AND(ISNUMBER(Tbl_Contributions[[#This Row],[نسبة الإدارة الخاصة به]]), Tbl_Contributions[[#This Row],[حصة الربح قبل الإدارة]]>0), Tbl_Contributions[[#This Row],[حصة الربح قبل الإدارة]] * Tbl_Contributions[[#This Row],[نسبة الإدارة الخاصة به]], 0) -> 9290.3226 | J43: =Tbl_Contributions[[#This Row],[حصة الربح قبل الإدارة]] - Tbl_Contributions[[#This Row],[نصيب الإدارة]] -> 37161.29 | K43: =Tbl_Contributions[[#This Row],[رأس مال المساهم]] + Tbl_Contributions[[#This Row],[صافي ربح المساهم]] -> 237161.29 | L43: =SUMIFS(Tbl_Distributions[المبلغ], Tbl_Distributions[المشروع المصدر], Tbl_Contributions[[#This Row],[اسم المشروع]], Tbl_Distributions[المساهم], Tbl_Contributions[[#This Row],[اسم المساهم]], Tbl_Distributions[نوع العملية], "<>تحويل بين المشاريع", Tbl_Distributions[نوع العملية], "<>مسحوب للإدارة") -> 0 | M43: =SUMIFS(Tbl_Distributions[المبلغ], Tbl_Distributions[المشروع المصدر], Tbl_Contributions[[#This Row],[اسم المشروع]], Tbl_Distributions[المساهم], Tbl_Contributions[[#This Row],[اسم المساهم]], Tbl_Distributions[نوع العملية], "مسحوب للإدارة") -> 0 | N43: =Tbl_Contributions[[#This Row],[إجمالي المستحق للمساهم]] - Tbl_Contributions[[#This Row],[المسحوبات (تتضمن رد رأس المال والأرباح)]] -> 237161.29 | O43: =IF(ISBLANK(Tbl_Contributions[[#This Row],[نسبة الإدارة الخاصة به]]), "تنبيه: نسبة الإدارة غير مسجلة", "مكتمل") -> مكتمل
A44: =IFERROR(INDEX([1]!Tbl_Projects[كود المشروع], MATCH([1]!Tbl_Contributions[[#This Row],[اسم المشروع]], [1]!Tbl_Projects[اسم المشروع], 0)), "") | B44: شقة الاكاديمية | D44: زكريا على | E44: 583333 | F44: =IF(SUMIFS(Tbl_Contributions[رأس مال المساهم], Tbl_Contributions[اسم المشروع], Tbl_Contributions[[#This Row],[اسم المشروع]])=0, 0, Tbl_Contributions[[#This Row],[رأس مال المساهم]]/SUMIFS(Tbl_Contributions[رأس مال المساهم], Tbl_Contributions[اسم المشروع], Tbl_Contributions[[#This Row],[اسم المشروع]])) -> 0.18817194 | G44: 0.2 | H44: =IFERROR(INDEX(Tbl_Projects[صافي الربح], MATCH(Tbl_Contributions[[#This Row],[اسم المشروع]], Tbl_Projects[اسم المشروع], 0)) * Tbl_Contributions[[#This Row],[نسبة مساهمته]], 0) -> 135483.79 | I44: =IF(AND(ISNUMBER(Tbl_Contributions[[#This Row],[نسبة الإدارة الخاصة به]]), Tbl_Contributions[[#This Row],[حصة الربح قبل الإدارة]]>0), Tbl_Contributions[[#This Row],[حصة الربح قبل الإدارة]] * Tbl_Contributions[[#This Row],[نسبة الإدارة الخاصة به]], 0) -> 27096.759 | J44: =Tbl_Contributions[[#This Row],[حصة الربح قبل الإدارة]] - Tbl_Contributions[[#This Row],[نصيب الإدارة]] -> 108387.03 | K44: =Tbl_Contributions[[#This Row],[رأس مال المساهم]] + Tbl_Contributions[[#This Row],[صافي ربح المساهم]] -> 691720.03 | L44: =SUMIFS(Tbl_Distributions[المبلغ], Tbl_Distributions[المشروع المصدر], Tbl_Contributions[[#This Row],[اسم المشروع]], Tbl_Distributions[المساهم], Tbl_Contributions[[#This Row],[اسم المساهم]], Tbl_Distributions[نوع العملية], "<>تحويل بين المشاريع", Tbl_Distributions[نوع العملية], "<>مسحوب للإدارة") -> 0 | M44: =SUMIFS(Tbl_Distributions[المبلغ], Tbl_Distributions[المشروع المصدر], Tbl_Contributions[[#This Row],[اسم المشروع]], Tbl_Distributions[المساهم], Tbl_Contributions[[#This Row],[اسم المساهم]], Tbl_Distributions[نوع العملية], "مسحوب للإدارة") -> 0 | N44: =Tbl_Contributions[[#This Row],[إجمالي المستحق للمساهم]] - Tbl_Contributions[[#This Row],[المسحوبات (تتضمن رد رأس المال والأرباح)]] -> 691720.03 | O44: =IF(ISBLANK(Tbl_Contributions[[#This Row],[نسبة الإدارة الخاصة به]]), "تنبيه: نسبة الإدارة غير مسجلة", "مكتمل") -> مكتمل
A45: =IFERROR(INDEX([1]!Tbl_Projects[كود المشروع], MATCH([1]!Tbl_Contributions[[#This Row],[اسم المشروع]], [1]!Tbl_Projects[اسم المشروع], 0)), "") | B45: شقة الاكاديمية | D45: رمضان رجب | E45: 61667 | F45: =IF(SUMIFS(Tbl_Contributions[رأس مال المساهم], Tbl_Contributions[اسم المشروع], Tbl_Contributions[[#This Row],[اسم المشروع]])=0, 0, Tbl_Contributions[[#This Row],[رأس مال المساهم]]/SUMIFS(Tbl_Contributions[رأس مال المساهم], Tbl_Contributions[اسم المشروع], Tbl_Contributions[[#This Row],[اسم المشروع]])) -> 0.019892581 | G45: 0.2 | H45: =IFERROR(INDEX(Tbl_Projects[صافي الربح], MATCH(Tbl_Contributions[[#This Row],[اسم المشروع]], Tbl_Projects[اسم المشروع], 0)) * Tbl_Contributions[[#This Row],[نسبة مساهمته]], 0) -> 14322.658 | I45: =IF(AND(ISNUMBER(Tbl_Contributions[[#This Row],[نسبة الإدارة الخاصة به]]), Tbl_Contributions[[#This Row],[حصة الربح قبل الإدارة]]>0), Tbl_Contributions[[#This Row],[حصة الربح قبل الإدارة]] * Tbl_Contributions[[#This Row],[نسبة الإدارة الخاصة به]], 0) -> 2864.5316 | J45: =Tbl_Contributions[[#This Row],[حصة الربح قبل الإدارة]] - Tbl_Contributions[[#This Row],[نصيب الإدارة]] -> 11458.126 | K45: =Tbl_Contributions[[#This Row],[رأس مال المساهم]] + Tbl_Contributions[[#This Row],[صافي ربح المساهم]] -> 73125.126 | L45: =SUMIFS(Tbl_Distributions[المبلغ], Tbl_Distributions[المشروع المصدر], Tbl_Contributions[[#This Row],[اسم المشروع]], Tbl_Distributions[المساهم], Tbl_Contributions[[#This Row],[اسم المساهم]], Tbl_Distributions[نوع العملية], "<>تحويل بين المشاريع", Tbl_Distributions[نوع العملية], "<>مسحوب للإدارة") -> 0 | M45: =SUMIFS(Tbl_Distributions[المبلغ], Tbl_Distributions[المشروع المصدر], Tbl_Contributions[[#This Row],[اسم المشروع]], Tbl_Distributions[المساهم], Tbl_Contributions[[#This Row],[اسم المساهم]], Tbl_Distributions[نوع العملية], "مسحوب للإدارة") -> 0 | N45: =Tbl_Contributions[[#This Row],[إجمالي المستحق للمساهم]] - Tbl_Contributions[[#This Row],[المسحوبات (تتضمن رد رأس المال والأرباح)]] -> 73125.126 | O45: =IF(ISBLANK(Tbl_Contributions[[#This Row],[نسبة الإدارة الخاصة به]]), "تنبيه: نسبة الإدارة غير مسجلة", "مكتمل") -> مكتمل
A46: =IFERROR(INDEX([1]!Tbl_Projects[كود المشروع], MATCH([1]!Tbl_Contributions[[#This Row],[اسم المشروع]], [1]!Tbl_Projects[اسم المشروع], 0)), "") | B46: شقة الاكاديمية | D46: اشرف ابراهيم | E46: 20833 | F46: =IF(SUMIFS(Tbl_Contributions[رأس مال المساهم], Tbl_Contributions[اسم المشروع], Tbl_Contributions[[#This Row],[اسم المشروع]])=0, 0, Tbl_Contributions[[#This Row],[رأس مال المساهم]]/SUMIFS(Tbl_Contributions[رأس مال المساهم], Tbl_Contributions[اسم المشروع], Tbl_Contributions[[#This Row],[اسم المشروع]])) -> 0.0067203226 | G46: 0.2 | H46: =IFERROR(INDEX(Tbl_Projects[صافي الربح], MATCH(Tbl_Contributions[[#This Row],[اسم المشروع]], Tbl_Projects[اسم المشروع], 0)) * Tbl_Contributions[[#This Row],[نسبة مساهمته]], 0) -> 4838.6323 | I46: =IF(AND(ISNUMBER(Tbl_Contributions[[#This Row],[نسبة الإدارة الخاصة به]]), Tbl_Contributions[[#This Row],[حصة الربح قبل الإدارة]]>0), Tbl_Contributions[[#This Row],[حصة الربح قبل الإدارة]] * Tbl_Contributions[[#This Row],[نسبة الإدارة الخاصة به]], 0) -> 967.72645 | J46: =Tbl_Contributions[[#This Row],[حصة الربح قبل الإدارة]] - Tbl_Contributions[[#This Row],[نصيب الإدارة]] -> 3870.9058 | K46: =Tbl_Contributions[[#This Row],[رأس مال المساهم]] + Tbl_Contributions[[#This Row],[صافي ربح المساهم]] -> 24703.906 | L46: =SUMIFS(Tbl_Distributions[المبلغ], Tbl_Distributions[المشروع المصدر], Tbl_Contributions[[#This Row],[اسم المشروع]], Tbl_Distributions[المساهم], Tbl_Contributions[[#This Row],[اسم المساهم]], Tbl_Distributions[نوع العملية], "<>تحويل بين المشاريع", Tbl_Distributions[نوع العملية], "<>مسحوب للإدارة") -> 0 | M46: =SUMIFS(Tbl_Distributions[المبلغ], Tbl_Distributions[المشروع المصدر], Tbl_Contributions[[#This Row],[اسم المشروع]], Tbl_Distributions[المساهم], Tbl_Contributions[[#This Row],[اسم المساهم]], Tbl_Distributions[نوع العملية], "مسحوب للإدارة") -> 0 | N46: =Tbl_Contributions[[#This Row],[إجمالي المستحق للمساهم]] - Tbl_Contributions[[#This Row],[المسحوبات (تتضمن رد رأس المال والأرباح)]] -> 24703.906 | O46: =IF(ISBLANK(Tbl_Contributions[[#This Row],[نسبة الإدارة الخاصة به]]), "تنبيه: نسبة الإدارة غير مسجلة", "مكتمل") -> مكتمل
A47: =IFERROR(INDEX([1]!Tbl_Projects[كود المشروع], MATCH([1]!Tbl_Contributions[[#This Row],[اسم المشروع]], [1]!Tbl_Projects[اسم المشروع], 0)), "") | B47: شقة الاكاديمية | D47: على ممدوح | E47: 140000 | F47: =IF(SUMIFS(Tbl_Contributions[رأس مال المساهم], Tbl_Contributions[اسم المشروع], Tbl_Contributions[[#This Row],[اسم المشروع]])=0, 0, Tbl_Contributions[[#This Row],[رأس مال المساهم]]/SUMIFS(Tbl_Contributions[رأس مال المساهم], Tbl_Contributions[اسم المشروع], Tbl_Contributions[[#This Row],[اسم المشروع]])) -> 0.04516129 | G47: 0.2 | H47: =IFERROR(INDEX(Tbl_Projects[صافي الربح], MATCH(Tbl_Contributions[[#This Row],[اسم المشروع]], Tbl_Projects[اسم المشروع], 0)) * Tbl_Contributions[[#This Row],[نسبة مساهمته]], 0) -> 32516.129 | I47: =IF(AND(ISNUMBER(Tbl_Contributions[[#This Row],[نسبة الإدارة الخاصة به]]), Tbl_Contributions[[#This Row],[حصة الربح قبل الإدارة]]>0), Tbl_Contributions[[#This Row],[حصة الربح قبل الإدارة]] * Tbl_Contributions[[#This Row],[نسبة الإدارة الخاصة به]], 0) -> 6503.2258 | J47: =Tbl_Contributions[[#This Row],[حصة الربح قبل الإدارة]] - Tbl_Contributions[[#This Row],[نصيب الإدارة]] -> 26012.903 | K47: =Tbl_Contributions[[#This Row],[رأس مال المساهم]] + Tbl_Contributions[[#This Row],[صافي ربح المساهم]] -> 166012.9 | L47: =SUMIFS(Tbl_Distributions[المبلغ], Tbl_Distributions[المشروع المصدر], Tbl_Contributions[[#This Row],[اسم المشروع]], Tbl_Distributions[المساهم], Tbl_Contributions[[#This Row],[اسم المساهم]], Tbl_Distributions[نوع العملية], "<>تحويل بين المشاريع", Tbl_Distributions[نوع العملية], "<>مسحوب للإدارة") -> 0 | M47: =SUMIFS(Tbl_Distributions[المبلغ], Tbl_Distributions[المشروع المصدر], Tbl_Contributions[[#This Row],[اسم المشروع]], Tbl_Distributions[المساهم], Tbl_Contributions[[#This Row],[اسم المساهم]], Tbl_Distributions[نوع العملية], "مسحوب للإدارة") -> 0 | N47: =Tbl_Contributions[[#This Row],[إجمالي المستحق للمساهم]] - Tbl_Contributions[[#This Row],[المسحوبات (تتضمن رد رأس المال والأرباح)]] -> 166012.9 | O47: =IF(ISBLANK(Tbl_Contributions[[#This Row],[نسبة الإدارة الخاصة به]]), "تنبيه: نسبة الإدارة غير مسجلة", "مكتمل") -> مكتمل
A48: =IFERROR(INDEX([1]!Tbl_Projects[كود المشروع], MATCH([1]!Tbl_Contributions[[#This Row],[اسم المشروع]], [1]!Tbl_Projects[اسم المشروع], 0)), "") | B48: شقة الاكاديمية | D48: الحاج خلف الارض | E48: 586667 | F48: =IF(SUMIFS(Tbl_Contributions[رأس مال المساهم], Tbl_Contributions[اسم المشروع], Tbl_Contributions[[#This Row],[اسم المشروع]])=0, 0, Tbl_Contributions[[#This Row],[رأس مال المساهم]]/SUMIFS(Tbl_Contributions[رأس مال المساهم], Tbl_Contributions[اسم المشروع], Tbl_Contributions[[#This Row],[اسم المشروع]])) -> 0.18924742 | G48: 0.2 | H48: =IFERROR(INDEX(Tbl_Projects[صافي الربح], MATCH(Tbl_Contributions[[#This Row],[اسم المشروع]], Tbl_Projects[اسم المشروع], 0)) * Tbl_Contributions[[#This Row],[نسبة مساهمته]], 0) -> 136258.14 | I48: =IF(AND(ISNUMBER(Tbl_Contributions[[#This Row],[نسبة الإدارة الخاصة به]]), Tbl_Contributions[[#This Row],[حصة الربح قبل الإدارة]]>0), Tbl_Contributions[[#This Row],[حصة الربح قبل الإدارة]] * Tbl_Contributions[[#This Row],[نسبة الإدارة الخاصة به]], 0) -> 27251.628 | J48: =Tbl_Contributions[[#This Row],[حصة الربح قبل الإدارة]] - Tbl_Contributions[[#This Row],[نصيب الإدارة]] -> 109006.51 | K48: =Tbl_Contributions[[#This Row],[رأس مال المساهم]] + Tbl_Contributions[[#This Row],[صافي ربح المساهم]] -> 695673.51 | L48: =SUMIFS(Tbl_Distributions[المبلغ], Tbl_Distributions[المشروع المصدر], Tbl_Contributions[[#This Row],[اسم المشروع]], Tbl_Distributions[المساهم], Tbl_Contributions[[#This Row],[اسم المساهم]], Tbl_Distributions[نوع العملية], "<>تحويل بين المشاريع", Tbl_Distributions[نوع العملية], "<>مسحوب للإدارة") -> 0 | M48: =SUMIFS(Tbl_Distributions[المبلغ], Tbl_Distributions[المشروع المصدر], Tbl_Contributions[[#This Row],[اسم المشروع]], Tbl_Distributions[المساهم], Tbl_Contributions[[#This Row],[اسم المساهم]], Tbl_Distributions[نوع العملية], "مسحوب للإدارة") -> 0 | N48: =Tbl_Contributions[[#This Row],[إجمالي المستحق للمساهم]] - Tbl_Contributions[[#This Row],[المسحوبات (تتضمن رد رأس المال والأرباح)]] -> 695673.51 | O48: =IF(ISBLANK(Tbl_Contributions[[#This Row],[نسبة الإدارة الخاصة به]]), "تنبيه: نسبة الإدارة غير مسجلة", "مكتمل") -> مكتمل
A49: =IFERROR(INDEX([1]!Tbl_Projects[كود المشروع], MATCH([1]!Tbl_Contributions[[#This Row],[اسم المشروع]], [1]!Tbl_Projects[اسم المشروع], 0)), "") | B49: شقة الاكاديمية | D49: جمعه خلف | E49: 40833 | F49: =IF(SUMIFS(Tbl_Contributions[رأس مال المساهم], Tbl_Contributions[اسم المشروع], Tbl_Contributions[[#This Row],[اسم المشروع]])=0, 0, Tbl_Contributions[[#This Row],[رأس مال المساهم]]/SUMIFS(Tbl_Contributions[رأس مال المساهم], Tbl_Contributions[اسم المشروع], Tbl_Contributions[[#This Row],[اسم المشروع]])) -> 0.013171935 | G49: 0.2 | H49: =IFERROR(INDEX(Tbl_Projects[صافي الربح], MATCH(Tbl_Contributions[[#This Row],[اسم المشروع]], Tbl_Projects[اسم المشروع], 0)) * Tbl_Contributions[[#This Row],[نسبة مساهمته]], 0) -> 9483.7935 | I49: =IF(AND(ISNUMBER(Tbl_Contributions[[#This Row],[نسبة الإدارة الخاصة به]]), Tbl_Contributions[[#This Row],[حصة الربح قبل الإدارة]]>0), Tbl_Contributions[[#This Row],[حصة الربح قبل الإدارة]] * Tbl_Contributions[[#This Row],[نسبة الإدارة الخاصة به]], 0) -> 1896.7587 | J49: =Tbl_Contributions[[#This Row],[حصة الربح قبل الإدارة]] - Tbl_Contributions[[#This Row],[نصيب الإدارة]] -> 7587.0348 | K49: =Tbl_Contributions[[#This Row],[رأس مال المساهم]] + Tbl_Contributions[[#This Row],[صافي ربح المساهم]] -> 48420.035 | L49: =SUMIFS(Tbl_Distributions[المبلغ], Tbl_Distributions[المشروع المصدر], Tbl_Contributions[[#This Row],[اسم المشروع]], Tbl_Distributions[المساهم], Tbl_Contributions[[#This Row],[اسم المساهم]], Tbl_Distributions[نوع العملية], "<>تحويل بين المشاريع", Tbl_Distributions[نوع العملية], "<>مسحوب للإدارة") -> 0 | M49: =SUMIFS(Tbl_Distributions[المبلغ], Tbl_Distributions[المشروع المصدر], Tbl_Contributions[[#This Row],[اسم المشروع]], Tbl_Distributions[المساهم], Tbl_Contributions[[#This Row],[اسم المساهم]], Tbl_Distributions[نوع العملية], "مسحوب للإدارة") -> 0 | N49: =Tbl_Contributions[[#This Row],[إجمالي المستحق للمساهم]] - Tbl_Contributions[[#This Row],[المسحوبات (تتضمن رد رأس المال والأرباح)]] -> 48420.035 | O49: =IF(ISBLANK(Tbl_Contributions[[#This Row],[نسبة الإدارة الخاصة به]]), "تنبيه: نسبة الإدارة غير مسجلة", "مكتمل") -> مكتمل
